[2024-04-30 11:05:37,951] root - INFO - Entered initiate_data_ingestion method of Data_Ingestion class
[2024-04-30 11:05:37,951] root - INFO - Downloading data from https://drive.google.com/file/d/1TP795GMoAsbO2ZlJCtdA0jDI-Iwl3KZR/view?usp=sharing into file artifacts\data_ingestion\data.zip
[2024-04-30 11:05:42,178] root - ERROR - Error occurred during data ingestion: Error occurred in Python script name [C:\Users\pc\end-to-end-defact-detaction\Defact_detaction\components\data_ingestion.py] line number [72] error message [Error occurred in Python script name [C:\Users\pc\end-to-end-defact-detaction\Defact_detaction\components\data_ingestion.py] line number [37] error message [HTTPSConnectionPool(host='doc-0s-5o-docs.googleusercontent.com', port=443): Max retries exceeded with url: /docs/securesc/ha0ro937gcuc7l7deffksulhg5h7mbp1/01rqshig5le1u5m558qokg1k9bnnhpdg/1714455300000/13598743524925930559/*/1TP795GMoAsbO2ZlJCtdA0jDI-Iwl3KZR?uuid=dbfd43f3-0289-4509-8d39-8e92be92329b (Caused by NameResolutionError("<urllib3.connection.HTTPSConnection object at 0x0000021DAE178148>: Failed to resolve 'doc-0s-5o-docs.googleusercontent.com' ([Errno 11001] getaddrinfo failed)"))]]
[2024-04-30 11:05:42,186] root - ERROR - Application exception occurred: Error occurred in Python script name [C:\Users\pc\end-to-end-defact-detaction\Defact_detaction\pipeline\training_pipeline.py] line number [18] error message [Error occurred in Python script name [C:\Users\pc\end-to-end-defact-detaction\Defact_detaction\components\data_ingestion.py] line number [72] error message [Error occurred in Python script name [C:\Users\pc\end-to-end-defact-detaction\Defact_detaction\components\data_ingestion.py] line number [37] error message [HTTPSConnectionPool(host='doc-0s-5o-docs.googleusercontent.com', port=443): Max retries exceeded with url: /docs/securesc/ha0ro937gcuc7l7deffksulhg5h7mbp1/01rqshig5le1u5m558qokg1k9bnnhpdg/1714455300000/13598743524925930559/*/1TP795GMoAsbO2ZlJCtdA0jDI-Iwl3KZR?uuid=dbfd43f3-0289-4509-8d39-8e92be92329b (Caused by NameResolutionError("<urllib3.connection.HTTPSConnection object at 0x0000021DAE178148>: Failed to resolve 'doc-0s-5o-docs.googleusercontent.com' ([Errno 11001] getaddrinfo failed)"))]]]
